<?xml version="1.0" ?>
<!-- =================================================================================== -->
<!-- |    This document was autogenerated by xacro from /home/robot/orangewood_ws/src/orangewood_simstack/owl/owl_description/urdf/6.5/robot_pneumatic.xacro | -->
<!-- |    EDITING THIS FILE BY HAND IS NOT RECOMMENDED                                 | -->
<!-- =================================================================================== -->
<robot name="owl_robot">
    <!-- Macro of OWL 6.5 without any end effector -->
    <link name="world" />
    <joint name="virtual_joint" type="fixed">
        <origin rpy="0 0 0" xyz="0.0 0.0 0.0" />
        <parent link="world" />
        <child link="base_link" />
    </joint>
    <link name="base_link">
        <inertial>
            <origin rpy="0 0 0" xyz="2.7395E-05 -0.01813 4.3722E-05" />
            <mass value="2.39" />
            <inertia ixx="0.0060063" ixy="-2.5541E-15" ixz="-2.5603E-07" iyy="0.0095451" iyz="5.1619E-15" izz="0.006006" />
        </inertial>
        <visual>
            <origin rpy="0 0 0" xyz="0 0 0" />
            <geometry>
                <mesh filename="package://owl_description/meshes/6.5/visual/owl_robot/base_link.stl" />
            </geometry>
            <material name="">
                <color rgba="0.89804 0.91765 0.92941 1" />
            </material>
        </visual>
        <collision>
            <origin rpy="0 0 0" xyz="0 0 0" />
            <geometry>
                <mesh filename="package://owl_description/meshes/6.5/collision/owl_robot/base_link.stl" />
            </geometry>
        </collision>
    </link>
    <link name="shoulder_link">
        <inertial>
            <origin rpy="0 0 0" xyz="0.00042134 0.034391 -0.10382" />
            <mass value="4.613" />
            <inertia ixx="0.0035279" ixy="-5.6452E-06" ixz="-9.4882E-07" iyy="0.0046955" iyz="0.00045199" izz="0.0048177" />
        </inertial>
        <visual>
            <origin rpy="0 0 0" xyz="0 0 0" />
            <geometry>
                <mesh filename="package://owl_description/meshes/6.5/visual/owl_robot/shoulder_link.stl" />
            </geometry>
            <material name="">
                <color rgba="0.89804 0.91765 0.92941 1" />
            </material>
        </visual>
        <collision>
            <origin rpy="0 0 0" xyz="0 0 0" />
            <geometry>
                <mesh filename="package://owl_description/meshes/6.5/collision/owl_robot/shoulder_link.stl" />
            </geometry>
        </collision>
    </link>
    <joint name="BJ" type="revolute">
        <origin rpy="-3.1416 0 0" xyz="0 0 0" />
        <parent link="base_link" />
        <child link="shoulder_link" />
        <axis xyz="0 0 1" />
        <limit effort="500" lower="-3.14" upper="3.14" velocity="50" />
    </joint>
    <link name="link1">
        <inertial>
            <origin rpy="0 0 0" xyz=" 0.17795 0.00011012 -0.085428" />
            <mass value="9.431" />
            <inertia ixx="0.0052455" ixy="1.4977E-05" ixz="2.6778E-05" iyy="0.028778" iyz="-3.8624E-06" izz="0.032177" />
        </inertial>
        <visual>
            <origin rpy="0 0 0" xyz="0 0 0" />
            <geometry>
                <mesh filename="package://owl_description/meshes/6.5/visual/owl_robot/link1.stl" />
            </geometry>
            <material name="">
                <color rgba="0.2 0.2 0.2 1.0" />
            </material>
        </visual>
        <collision>
            <origin rpy="0 0 0" xyz="0 0 0" />
            <geometry>
                <mesh filename="package://owl_description/meshes/6.5/collision/owl_robot/link1.stl" />
            </geometry>
        </collision>
    </link>
    <joint name="SJ" type="revolute">
        <origin rpy="0.58944 1.5675 -0.983" xyz="0.00018339 0.066603 -0.1405" />
        <parent link="shoulder_link" />
        <child link="link1" />
        <axis xyz="0.0027142 -0.0011243 1" />
        <limit effort="500" lower="-1.6" upper="1.6" velocity="50" />
    </joint>
    <link name="elbow_link">
        <inertial>
            <origin rpy="0 0 0" xyz="0.00023616 -0.028792 -0.029823" />
            <mass value="4.613" />
            <inertia ixx="0.0023499" ixy="-2.7675E-06" ixz="-4.1087E-07" iyy="0.0030181" iyz="-0.00026183" izz="0.0035661" />
        </inertial>
        <visual>
            <origin rpy="0 0 0" xyz="0 0 0" />
            <geometry>
                <mesh filename="package://owl_description/meshes/6.5/visual/owl_robot/elbow_link.stl" />
            </geometry>
            <material name="">
                <color rgba="0.89804 0.91765 0.92941 1" />
            </material>
        </visual>
        <collision>
            <origin rpy="0 0 0" xyz="0 0 0" />
            <geometry>
                <mesh filename="package://owl_description/meshes/6.5/collision/owl_robot/elbow_link.stl" />
            </geometry>
        </collision>
    </link>
    <joint name="EJ" type="revolute">
        <origin rpy="3.1389 -0.0018334 -1.5781" xyz="0.35575 0 -0.00096557" />
        <parent link="link1" />
        <child link="elbow_link" />
        <axis xyz="0 0 1" />
        <limit effort="500" lower="-2.8" upper="3.14" velocity="50" />
    </joint>
    <link name="link2">
        <inertial>
            <origin rpy="0 0 0" xyz="0.00015054 -0.075078 0.13834" />
            <mass value="2.4407" />
            <inertia ixx="0.009134" ixy="-3.9978E-06" ixz="-4.8015E-06" iyy="0.010823" iyz="0.00068065" izz="0.0041094" />
        </inertial>
        <visual>
            <origin rpy="0 0 0" xyz="0 0 0" />
            <geometry>
                <mesh filename="package://owl_description/meshes/6.5/visual/owl_robot/link2.stl" />
            </geometry>
            <material name="">
                <color rgba="0.2 0.2 0.2 1.0" />
            </material>
        </visual>
        <collision>
            <origin rpy="0 0 0" xyz="0 0 0" />
            <geometry>
                <mesh filename="package://owl_description/meshes/6.5/collision/owl_robot/link2.stl" />
            </geometry>
        </collision>
    </link>
    <joint name="W1J" type="revolute">
        <origin rpy="1.5708 -0.0023608 0" xyz="0.00019567 -0.079361 -0.066603" />
        <parent link="elbow_link" />
        <child link="link2" />
        <axis xyz="0 0 -1" />
        <limit effort="500" lower="-2.84489" upper="2.84489" velocity="50" />
    </joint>
    <link name="w2w3_link">
        <inertial>
            <origin rpy="0 0 0" xyz="0.00025923 0.029764 0.027271" />
            <mass value="3.118" />
            <inertia ixx="0.0014884" ixy="2.1526E-06" ixz="6.6731E-06" iyy="0.0016882" iyz="0.0001816" izz="0.0019291" />
        </inertial>
        <visual>
            <origin rpy="0 0 0" xyz="0 0 0" />
            <geometry>
                <mesh filename="package://owl_description/meshes/6.5/visual/owl_robot/w2w3_link.stl" />
            </geometry>
            <material name="">
                <color rgba="0.2 0.2 0.2 1.0" />
            </material>
        </visual>
        <collision>
            <origin rpy="0 0 0" xyz="0 0 0" />
            <geometry>
                <mesh filename="package://owl_description/meshes/6.5/collision/owl_robot/w2w3_link.stl" />
            </geometry>
        </collision>
    </link>
    <joint name="W2J" type="revolute">
        <origin rpy="2.745 -1.5667 -1.1726" xyz="0 0 0.27639" />
        <parent link="link2" />
        <child link="w2w3_link" />
        <axis xyz="0.0037507 -0.00083382 0.99999" />
        <limit effort="500" lower="-1.6" upper="0.78" velocity="50" />
        <safety_controller k_position="100" k_velocity="1.5" soft_lower_limit="-1.857" soft_upper_limit="0.8" />
    </joint>
    <link name="end_effector_link">
        <inertial>
            <origin rpy="0 0 0" xyz="2.2451E-05 -0.00060487 0.098537" />
            <mass value="0.188" />
            <inertia ixx="0.00017935" ixy="-3.2299E-08" ixz="-2.1374E-07" iyy="0.00017907" iyz="-4.545E-07" izz="0.00025742" />
        </inertial>
        <visual>
            <origin rpy="0 0 0" xyz="0 0 0" />
            <geometry>
                <mesh filename="package://owl_description/meshes/6.5/visual/owl_robot/end_effector_link.stl" />
            </geometry>
            <material name="">
                <color rgba="0.89804 0.91765 0.92941 1" />
            </material>
        </visual>
        <collision>
            <origin rpy="0 0 0" xyz="0 0 0" />
            <geometry>
                <mesh filename="package://owl_description/meshes/6.5/collision/owl_robot/end_effector_link.stl" />
            </geometry>
        </collision>
    </link>
    <joint name="W3J" type="revolute">
        <origin rpy="-1.2578 -1.5668 -0.31786" xyz="0 0 0" />
        <limit effort="500" lower="-3.1" upper="3.1" velocity="50" />
        <parent link="w2w3_link" />
        <child link="end_effector_link" />
        <axis xyz="0 0 1" />
    </joint>
    <link name="tcp">
        <inertial>
            <origin rpy="0 0 0" xyz="0 0 0" />
            <mass value="1e-9" />
            <inertia ixx="0" ixy="0" ixz="0" iyy="0" iyz="0" izz="0" />
        </inertial>
    </link>
    <joint name="tcp_frame" type="fixed">
        <origin rpy="5.94633e-15 -1.33504e-14 -1.5708" xyz="4.33681e-19 0 0.1225" />
        <parent link="end_effector_link" />
        <child link="tcp" />
        <axis xyz="0 0 0" />
    </joint>
    <link name="pnt_gripper">
        <visual>
            <origin rpy="0 1.57 1.57" xyz="0.034 -0.047 0.21" />
            <geometry>
                <mesh filename="package://owl_description/meshes/grippers/pneumatic/pneumatic.stl" scale="0.001 0.001 0.001" />
            </geometry>
            <material name="">
                <color rgba="0.79216 0.81961 0.93333 1" />
            </material>
        </visual>
        <collision>
            <origin rpy="0 1.57 1.57" xyz="0.034 -0.047 0.21" />
            <geometry>
                <mesh filename="package://owl_description/meshes/grippers/pneumatic/pneumatic.stl" scale="0.001 0.001 0.001" />
            </geometry>
        </collision>
        <inertial>
            <mass value="0.1" />
            <origin xyz="0 0 0" rpy="0 0 0" />
            <inertia ixx="0.03" iyy="0.03" izz="0.03" ixy="0.0" ixz="0.0" iyz="0.0" />
        </inertial>
    </link>
    <joint name="gripper_holder_joint" type="fixed">
        <origin rpy="0 0 0" xyz="0.0 0.0 0.0" />
        <parent link="tcp" />
        <child link="pnt_gripper" />
        <axis xyz="0 0 0" />
    </joint>
    <transmission name="trans_BJ">
        <type>transmission_interface/SimpleTransmission</type>
        <joint name="BJ">
            <hardwareInterface>hardware_interface/PositionJointInterface</hardwareInterface>
        </joint>
        <actuator name="BJ_motor">
            <hardwareInterface>hardware_interface/PositionJointInterface</hardwareInterface>
            <mechanicalReduction>1</mechanicalReduction>
        </actuator>
    </transmission>
    <transmission name="trans_SJ">
        <type>transmission_interface/SimpleTransmission</type>
        <joint name="SJ">
            <hardwareInterface>hardware_interface/PositionJointInterface</hardwareInterface>
        </joint>
        <actuator name="SJ_motor">
            <hardwareInterface>hardware_interface/PositionJointInterface</hardwareInterface>
            <mechanicalReduction>1</mechanicalReduction>
        </actuator>
    </transmission>
    <transmission name="trans_EJ">
        <type>transmission_interface/SimpleTransmission</type>
        <joint name="EJ">
            <hardwareInterface>hardware_interface/PositionJointInterface</hardwareInterface>
        </joint>
        <actuator name="EJ_motor">
            <hardwareInterface>hardware_interface/PositionJointInterface</hardwareInterface>
            <mechanicalReduction>1</mechanicalReduction>
        </actuator>
    </transmission>
    <transmission name="trans_W1J">
        <type>transmission_interface/SimpleTransmission</type>
        <joint name="W1J">
            <hardwareInterface>hardware_interface/PositionJointInterface</hardwareInterface>
        </joint>
        <actuator name="W1J_motor">
            <hardwareInterface>hardware_interface/PositionJointInterface</hardwareInterface>
            <mechanicalReduction>1</mechanicalReduction>
        </actuator>
    </transmission>
    <transmission name="trans_W2J">
        <type>transmission_interface/SimpleTransmission</type>
        <joint name="W2J">
            <hardwareInterface>hardware_interface/PositionJointInterface</hardwareInterface>
        </joint>
        <actuator name="W2J_motor">
            <hardwareInterface>hardware_interface/PositionJointInterface</hardwareInterface>
            <mechanicalReduction>1</mechanicalReduction>
        </actuator>
    </transmission>
    <transmission name="trans_W3J">
        <type>transmission_interface/SimpleTransmission</type>
        <joint name="W3J">
            <hardwareInterface>hardware_interface/PositionJointInterface</hardwareInterface>
        </joint>
        <actuator name="W3J_motor">
            <hardwareInterface>hardware_interface/PositionJointInterface</hardwareInterface>
            <mechanicalReduction>1</mechanicalReduction>
        </actuator>
    </transmission>
    <gazebo>
        <plugin name="gazebo_ros_control" filename="libgazebo_ros_control.so">
            <robotNamespace>/</robotNamespace>
        </plugin>
    </gazebo>
</robot>

